Workbook

Sheet Dashboard
A1: CodeCritters Inc. - Trial Balance Comparison Dashboard
A2: PythonMuse LLC | Training & Demo Template
A4: Materiality Thresholds
A5: Comparison | B5: $ Threshold | C5: % Threshold
A6: Year-over-Year | B6: 2500 | C6: 0.15
A7: Month-over-Month | B7: 2500 | C7: 0.2
A9: Flag Counts
A10: YoY flags | B10: =COUNTIF(YoY_Variance!I3:I10000,"FLAG")
A11: MoM flags | B11: =COUNTIF(MoM_Variance!J3:J10000,"FLAG")
A13: Reconciliation Check (Assets = Liabilities + Equity, net of contras)
A14: Year | B14: Month | C14: Assets (net) | D14: Liabilities + Equity (net) | E14: Diff | F14: Status
A15: 2025 | B15: Jan | C15: =SUMIF('TB_2025'!$C$3:$C$34,"Asset",'TB_2025'!$D$3:$D$34)-SUMIF('TB_2025'!$B$3:$B$34,"Accumulated Depreciation",'TB_2025'!$D$3:$D$34)*2 | D15: =SUMIF('TB_2025'!$C$3:$C$34,"Liability",'TB_2025'!$D$3:$D$34)+SUMIF('TB_2025'!$C$3:$C$34,"Equity",'TB_2025'!$D$3:$D$34)-SUMIF('TB_2025'!$B$3:$B$34,"Owner Draws",'TB_2025'!$D$3:$D$34)*2 | E15: =C15-D15 | F15: =IF(ROUND(E15,2)=0,"OK","MISMATCH")
A16: 2025 | B16: Feb | C16: =SUMIF('TB_2025'!$C$3:$C$34,"Asset",'TB_2025'!$E$3:$E$34)-SUMIF('TB_2025'!$B$3:$B$34,"Accumulated Depreciation",'TB_2025'!$E$3:$E$34)*2 | D16: =SUMIF('TB_2025'!$C$3:$C$34,"Liability",'TB_2025'!$E$3:$E$34)+SUMIF('TB_2025'!$C$3:$C$34,"Equity",'TB_2025'!$E$3:$E$34)-SUMIF('TB_2025'!$B$3:$B$34,"Owner Draws",'TB_2025'!$E$3:$E$34)*2 | E16: =C16-D16 | F16: =IF(ROUND(E16,2)=0,"OK","MISMATCH")
A17: 2025 | B17: Mar | C17: =SUMIF('TB_2025'!$C$3:$C$34,"Asset",'TB_2025'!$F$3:$F$34)-SUMIF('TB_2025'!$B$3:$B$34,"Accumulated Depreciation",'TB_2025'!$F$3:$F$34)*2 | D17: =SUMIF('TB_2025'!$C$3:$C$34,"Liability",'TB_2025'!$F$3:$F$34)+SUMIF('TB_2025'!$C$3:$C$34,"Equity",'TB_2025'!$F$3:$F$34)-SUMIF('TB_2025'!$B$3:$B$34,"Owner Draws",'TB_2025'!$F$3:$F$34)*2 | E17: =C17-D17 | F17: =IF(ROUND(E17,2)=0,"OK","MISMATCH")
A18: 2025 | B18: Apr | C18: =SUMIF('TB_2025'!$C$3:$C$34,"Asset",'TB_2025'!$G$3:$G$34)-SUMIF('TB_2025'!$B$3:$B$34,"Accumulated Depreciation",'TB_2025'!$G$3:$G$34)*2 | D18: =SUMIF('TB_2025'!$C$3:$C$34,"Liability",'TB_2025'!$G$3:$G$34)+SUMIF('TB_2025'!$C$3:$C$34,"Equity",'TB_2025'!$G$3:$G$34)-SUMIF('TB_2025'!$B$3:$B$34,"Owner Draws",'TB_2025'!$G$3:$G$34)*2 | E18: =C18-D18 | F18: =IF(ROUND(E18,2)=0,"OK","MISMATCH")
A19: 2026 | B19: Jan | C19: =SUMIF('TB_2026'!$C$3:$C$34,"Asset",'TB_2026'!$D$3:$D$34)-SUMIF('TB_2026'!$B$3:$B$34,"Accumulated Depreciation",'TB_2026'!$D$3:$D$34)*2 | D19: =SUMIF('TB_2026'!$C$3:$C$34,"Liability",'TB_2026'!$D$3:$D$34)+SUMIF('TB_2026'!$C$3:$C$34,"Equity",'TB_2026'!$D$3:$D$34)-SUMIF('TB_2026'!$B$3:$B$34,"Owner Draws",'TB_2026'!$D$3:$D$34)*2 | E19: =C19-D19 | F19: =IF(ROUND(E19,2)=0,"OK","MISMATCH")
A20: 2026 | B20: Feb | C20: =SUMIF('TB_2026'!$C$3:$C$34,"Asset",'TB_2026'!$E$3:$E$34)-SUMIF('TB_2026'!$B$3:$B$34,"Accumulated Depreciation",'TB_2026'!$E$3:$E$34)*2 | D20: =SUMIF('TB_2026'!$C$3:$C$34,"Liability",'TB_2026'!$E$3:$E$34)+SUMIF('TB_2026'!$C$3:$C$34,"Equity",'TB_2026'!$E$3:$E$34)-SUMIF('TB_2026'!$B$3:$B$34,"Owner Draws",'TB_2026'!$E$3:$E$34)*2 | E20: =C20-D20 | F20: =IF(ROUND(E20,2)=0,"OK","MISMATCH")
A21: 2026 | B21: Mar | C21: =SUMIF('TB_2026'!$C$3:$C$34,"Asset",'TB_2026'!$F$3:$F$34)-SUMIF('TB_2026'!$B$3:$B$34,"Accumulated Depreciation",'TB_2026'!$F$3:$F$34)*2 | D21: =SUMIF('TB_2026'!$C$3:$C$34,"Liability",'TB_2026'!$F$3:$F$34)+SUMIF('TB_2026'!$C$3:$C$34,"Equity",'TB_2026'!$F$3:$F$34)-SUMIF('TB_2026'!$B$3:$B$34,"Owner Draws",'TB_2026'!$F$3:$F$34)*2 | E21: =C21-D21 | F21: =IF(ROUND(E21,2)=0,"OK","MISMATCH")
A22: 2026 | B22: Apr | C22: =SUMIF('TB_2026'!$C$3:$C$34,"Asset",'TB_2026'!$G$3:$G$34)-SUMIF('TB_2026'!$B$3:$B$34,"Accumulated Depreciation",'TB_2026'!$G$3:$G$34)*2 | D22: =SUMIF('TB_2026'!$C$3:$C$34,"Liability",'TB_2026'!$G$3:$G$34)+SUMIF('TB_2026'!$C$3:$C$34,"Equity",'TB_2026'!$G$3:$G$34)-SUMIF('TB_2026'!$B$3:$B$34,"Owner Draws",'TB_2026'!$G$3:$G$34)*2 | E22: =C22-D22 | F22: =IF(ROUND(E22,2)=0,"OK","MISMATCH")

Sheet TB_2025
A1: Trial Balance - 2025 (Prior Year) (source data, do not edit)
A2: Account Code | B2: Account | C2: Type | D2: Jan | E2: Feb | F2: Mar | G2: Apr
A3: 1000 | B3: Checking | C3: Asset | D3: 7600 | E3: 11270 | F3: 18855 | G3: 27430
A4: 1010 | B4: Savings | C4: Asset | D4: 20000 | E4: 20000 | F4: 20000 | G4: 20000
A5: 1200 | B5: Accounts Receivable | C5: Asset | D5: 14000 | E5: 14500 | F5: 15000 | G5: 15200
A6: 1300 | B6: Inventory - Raw Materials | C6: Asset | D6: 8000 | E6: 8200 | F6: 8400 | G6: 8600
A7: 1310 | B7: Inventory - Finished Goods | C7: Asset | D7: 11000 | E7: 11200 | F7: 11400 | G7: 11600
A8: 1400 | B8: Prepaid Insurance | C8: Asset | D8: 2400 | E8: 2200 | F8: 2000 | G8: 1800
A9: 1500 | B9: Equipment | C9: Asset | D9: 45000 | E9: 45000 | F9: 45000 | G9: 45000
A10: 1510 | B10: Accumulated Depreciation | C10: Asset | D10: 9800 | E10: 10600 | F10: 11400 | G10: 12200
A11: 2000 | B11: Accounts Payable | C11: Liability | D11: 7000 | E11: 7200 | F11: 7400 | G11: 7600
A12: 2100 | B12: Credit Card Payable | C12: Liability | D12: 3200 | E12: 3300 | F12: 3100 | G12: 3400
A13: 2200 | B13: Sales Tax Payable | C13: Liability | D13: 1800 | E13: 1850 | F13: 1900 | G13: 1950
A14: 2300 | B14: Payroll Liabilities | C14: Liability | D14: 2200 | E14: 2200 | F14: 2300 | G14: 2300
... A34: 6090 | B34: Office Supplies | C34: Expense | D34: 150 | E34: 140 | F34: 160 | G34: 155

Sheet TB_2026
A1: Trial Balance - 2026 (Current Year) (source data, do not edit)
A2: Account Code | B2: Account | C2: Type | D2: Jan | E2: Feb | F2: Mar | G2: Apr
A3: 1000 | B3: Checking | C3: Asset | D3: 42870 | E3: 47175 | F3: 41325 | G3: 41385
A4: 1010 | B4: Savings | C4: Asset | D4: 20000 | E4: 20000 | F4: 20000 | G4: 20000
A5: 1200 | B5: Accounts Receivable | C5: Asset | D5: 15400 | E5: 15700 | F5: 16100 | G5: 24800
A6: 1300 | B6: Inventory - Raw Materials | C6: Asset | D6: 8700 | E6: 8850 | F6: 9200 | G6: 9500
A7: 1310 | B7: Inventory - Finished Goods | C7: Asset | D7: 11700 | E7: 11900 | F7: 12100 | G7: 12300
A8: 1400 | B8: Prepaid Insurance | C8: Asset | D8: 1600 | E8: 1400 | F8: 1200 | G8: 1000
A9: 1500 | B9: Equipment | C9: Asset | D9: 45000 | E9: 45000 | F9: 46800 | G9: 46800
A10: 1510 | B10: Accumulated Depreciation | C10: Asset | D10: 13000 | E10: 13800 | F10: 14600 | G10: 15400
A11: 2000 | B11: Accounts Payable | C11: Liability | D11: 7700 | E11: 7900 | F11: 8100 | G11: 8300
A12: 2100 | B12: Credit Card Payable | C12: Liability | D12: 3500 | E12: 3600 | F12: 3450 | G12: 4700
A13: 2200 | B13: Sales Tax Payable | C13: Liability | D13: 1980 | E13: 2020 | F13: 2060 | G13: 2100
A14: 2300 | B14: Payroll Liabilities | C14: Liability | D14: 2350 | E14: 2350 | F14: 2400 | G14: 2400
... A34: 6090 | B34: Office Supplies | C34: Expense | D34: 160 | E34: 150 | F34: 900 | G34: 170

Sheet YoY_Variance
A1: Year-over-Year Variance - same month, 2026 vs. 2025
A2: Account Code | B2: Account | C2: Type | D2: Month | E2: Prior (2025) | F2: Current (2026) | G2: $ Var | H2: % Var | I2: Flag
A3: ='TB_2025'!A3 | B3: ='TB_2025'!B3 | C3: ='TB_2025'!C3 | D3: Jan | E3: ='TB_2025'!D3 | F3: ='TB_2026'!D3 | G3: =F3-E3 | H3: =IF(E3=0,"",G3/ABS(E3)) | I3: =IF(AND(ABS(G3)>Dashboard!$B$6,ISNUMBER(H3),ABS(H3)>Dashboard!$C$6),"FLAG","")
A4: ='TB_2025'!A3 | B4: ='TB_2025'!B3 | C4: ='TB_2025'!C3 | D4: Feb | E4: ='TB_2025'!E3 | F4: ='TB_2026'!E3 | G4: =F4-E4 | H4: =IF(E4=0,"",G4/ABS(E4)) | I4: =IF(AND(ABS(G4)>Dashboard!$B$6,ISNUMBER(H4),ABS(H4)>Dashboard!$C$6),"FLAG","")
A5: ='TB_2025'!A3 | B5: ='TB_2025'!B3 | C5: ='TB_2025'!C3 | D5: Mar | E5: ='TB_2025'!F3 | F5: ='TB_2026'!F3 | G5: =F5-E5 | H5: =IF(E5=0,"",G5/ABS(E5)) | I5: =IF(AND(ABS(G5)>Dashboard!$B$6,ISNUMBER(H5),ABS(H5)>Dashboard!$C$6),"FLAG","")
A6: ='TB_2025'!A3 | B6: ='TB_2025'!B3 | C6: ='TB_2025'!C3 | D6: Apr | E6: ='TB_2025'!G3 | F6: ='TB_2026'!G3 | G6: =F6-E6 | H6: =IF(E6=0,"",G6/ABS(E6)) | I6: =IF(AND(ABS(G6)>Dashboard!$B$6,ISNUMBER(H6),ABS(H6)>Dashboard!$C$6),"FLAG","")
A7: ='TB_2025'!A4 | B7: ='TB_2025'!B4 | C7: ='TB_2025'!C4 | D7: Jan | E7: ='TB_2025'!D4 | F7: ='TB_2026'!D4 | G7: =F7-E7 | H7: =IF(E7=0,"",G7/ABS(E7)) | I7: =IF(AND(ABS(G7)>Dashboard!$B$6,ISNUMBER(H7),ABS(H7)>Dashboard!$C$6),"FLAG","")
A8: ='TB_2025'!A4 | B8: ='TB_2025'!B4 | C8: ='TB_2025'!C4 | D8: Feb | E8: ='TB_2025'!E4 | F8: ='TB_2026'!E4 | G8: =F8-E8 | H8: =IF(E8=0,"",G8/ABS(E8)) | I8: =IF(AND(ABS(G8)>Dashboard!$B$6,ISNUMBER(H8),ABS(H8)>Dashboard!$C$6),"FLAG","")
A9: ='TB_2025'!A4 | B9: ='TB_2025'!B4 | C9: ='TB_2025'!C4 | D9: Mar | E9: ='TB_2025'!F4 | F9: ='TB_2026'!F4 | G9: =F9-E9 | H9: =IF(E9=0,"",G9/ABS(E9)) | I9: =IF(AND(ABS(G9)>Dashboard!$B$6,ISNUMBER(H9),ABS(H9)>Dashboard!$C$6),"FLAG","")
A10: ='TB_2025'!A4 | B10: ='TB_2025'!B4 | C10: ='TB_2025'!C4 | D10: Apr | E10: ='TB_2025'!G4 | F10: ='TB_2026'!G4 | G10: =F10-E10 | H10: =IF(E10=0,"",G10/ABS(E10)) | I10: =IF(AND(ABS(G10)>Dashboard!$B$6,ISNUMBER(H10),ABS(H10)>Dashboard!$C$6),"FLAG","")
A11: ='TB_2025'!A5 | B11: ='TB_2025'!B5 | C11: ='TB_2025'!C5 | D11: Jan | E11: ='TB_2025'!D5 | F11: ='TB_2026'!D5 | G11: =F11-E11 | H11: =IF(E11=0,"",G11/ABS(E11)) | I11: =IF(AND(ABS(G11)>Dashboard!$B$6,ISNUMBER(H11),ABS(H11)>Dashboard!$C$6),"FLAG","")
A12: ='TB_2025'!A5 | B12: ='TB_2025'!B5 | C12: ='TB_2025'!C5 | D12: Feb | E12: ='TB_2025'!E5 | F12: ='TB_2026'!E5 | G12: =F12-E12 | H12: =IF(E12=0,"",G12/ABS(E12)) | I12: =IF(AND(ABS(G12)>Dashboard!$B$6,ISNUMBER(H12),ABS(H12)>Dashboard!$C$6),"FLAG","")
A13: ='TB_2025'!A5 | B13: ='TB_2025'!B5 | C13: ='TB_2025'!C5 | D13: Mar | E13: ='TB_2025'!F5 | F13: ='TB_2026'!F5 | G13: =F13-E13 | H13: =IF(E13=0,"",G13/ABS(E13)) | I13: =IF(AND(ABS(G13)>Dashboard!$B$6,ISNUMBER(H13),ABS(H13)>Dashboard!$C$6),"FLAG","")
A14: ='TB_2025'!A5 | B14: ='TB_2025'!B5 | C14: ='TB_2025'!C5 | D14: Apr | E14: ='TB_2025'!G5 | F14: ='TB_2026'!G5 | G14: =F14-E14 | H14: =IF(E14=0,"",G14/ABS(E14)) | I14: =IF(AND(ABS(G14)>Dashboard!$B$6,ISNUMBER(H14),ABS(H14)>Dashboard!$C$6),"FLAG","")
A15: ='TB_2025'!A6 | B15: ='TB_2025'!B6 | C15: ='TB_2025'!C6 | D15: Jan | E15: ='TB_2025'!D6 | F15: ='TB_2026'!D6 | G15: =F15-E15 | H15: =IF(E15=0,"",G15/ABS(E15)) | I15: =IF(AND(ABS(G15)>Dashboard!$B$6,ISNUMBER(H15),ABS(H15)>Dashboard!$C$6),"FLAG","")
A16: ='TB_2025'!A6 | B16: ='TB_2025'!B6 | C16: ='TB_2025'!C6 | D16: Feb | E16: ='TB_2025'!E6 | F16: ='TB_2026'!E6 | G16: =F16-E16 | H16: =IF(E16=0,"",G16/ABS(E16)) | I16: =IF(AND(ABS(G16)>Dashboard!$B$6,ISNUMBER(H16),ABS(H16)>Dashboard!$C$6),"FLAG","")
A17: ='TB_2025'!A6 | B17: ='TB_2025'!B6 | C17: ='TB_2025'!C6 | D17: Mar | E17: ='TB_2025'!F6 | F17: ='TB_2026'!F6 | G17: =F17-E17 | H17: =IF(E17=0,"",G17/ABS(E17)) | I17: =IF(AND(ABS(G17)>Dashboard!$B$6,ISNUMBER(H17),ABS(H17)>Dashboard!$C$6),"FLAG","")
A18: ='TB_2025'!A6 | B18: ='TB_2025'!B6 | C18: ='TB_2025'!C6 | D18: Apr | E18: ='TB_2025'!G6 | F18: ='TB_2026'!G6 | G18: =F18-E18 | H18: =IF(E18=0,"",G18/ABS(E18)) | I18: =IF(AND(ABS(G18)>Dashboard!$B$6,ISNUMBER(H18),ABS(H18)>Dashboard!$C$6),"FLAG","")
A19: ='TB_2025'!A7 | B19: ='TB_2025'!B7 | C19: ='TB_2025'!C7 | D19: Jan | E19: ='TB_2025'!D7 | F19: ='TB_2026'!D7 | G19: =F19-E19 | H19: =IF(E19=0,"",G19/ABS(E19)) | I19: =IF(AND(ABS(G19)>Dashboard!$B$6,ISNUMBER(H19),ABS(H19)>Dashboard!$C$6),"FLAG","")
A20: ='TB_2025'!A7 | B20: ='TB_2025'!B7 | C20: ='TB_2025'!C7 | D20: Feb | E20: ='TB_2025'!E7 | F20: ='TB_2026'!E7 | G20: =F20-E20 | H20: =IF(E20=0,"",G20/ABS(E20)) | I20: =IF(AND(ABS(G20)>Dashboard!$B$6,ISNUMBER(H20),ABS(H20)>Dashboard!$C$6),"FLAG","")
A21: ='TB_2025'!A7 | B21: ='TB_2025'!B7 | C21: ='TB_2025'!C7 | D21: Mar | E21: ='TB_2025'!F7 | F21: ='TB_2026'!F7 | G21: =F21-E21 | H21: =IF(E21=0,"",G21/ABS(E21)) | I21: =IF(AND(ABS(G21)>Dashboard!$B$6,ISNUMBER(H21),ABS(H21)>Dashboard!$C$6),"FLAG","")
A22: ='TB_2025'!A7 | B22: ='TB_2025'!B7 | C22: ='TB_2025'!C7 | D22: Apr | E22: ='TB_2025'!G7 | F22: ='TB_2026'!G7 | G22: =F22-E22 | H22: =IF(E22=0,"",G22/ABS(E22)) | I22: =IF(AND(ABS(G22)>Dashboard!$B$6,ISNUMBER(H22),ABS(H22)>Dashboard!$C$6),"FLAG","")
A23: ='TB_2025'!A8 | B23: ='TB_2025'!B8 | C23: ='TB_2025'!C8 | D23: Jan | E23: ='TB_2025'!D8 | F23: ='TB_2026'!D8 | G23: =F23-E23 | H23: =IF(E23=0,"",G23/ABS(E23)) | I23: =IF(AND(ABS(G23)>Dashboard!$B$6,ISNUMBER(H23),ABS(H23)>Dashboard!$C$6),"FLAG","")
A24: ='TB_2025'!A8 | B24: ='TB_2025'!B8 | C24: ='TB_2025'!C8 | D24: Feb | E24: ='TB_2025'!E8 | F24: ='TB_2026'!E8 | G24: =F24-E24 | H24: =IF(E24=0,"",G24/ABS(E24)) | I24: =IF(AND(ABS(G24)>Dashboard!$B$6,ISNUMBER(H24),ABS(H24)>Dashboard!$C$6),"FLAG","")
A25: ='TB_2025'!A8 | B25: ='TB_2025'!B8 | C25: ='TB_2025'!C8 | D25: Mar | E25: ='TB_2025'!F8 | F25: ='TB_2026'!F8 | G25: =F25-E25 | H25: =IF(E25=0,"",G25/ABS(E25)) | I25: =IF(AND(ABS(G25)>Dashboard!$B$6,ISNUMBER(H25),ABS(H25)>Dashboard!$C$6),"FLAG","")
A26: ='TB_2025'!A8 | B26: ='TB_2025'!B8 | C26: ='TB_2025'!C8 | D26: Apr | E26: ='TB_2025'!G8 | F26: ='TB_2026'!G8 | G26: =F26-E26 | H26: =IF(E26=0,"",G26/ABS(E26)) | I26: =IF(AND(ABS(G26)>Dashboard!$B$6,ISNUMBER(H26),ABS(H26)>Dashboard!$C$6),"FLAG","")
A27: ='TB_2025'!A9 | B27: ='TB_2025'!B9 | C27: ='TB_2025'!C9 | D27: Jan | E27: ='TB_2025'!D9 | F27: ='TB_2026'!D9 | G27: =F27-E27 | H27: =IF(E27=0,"",G27/ABS(E27)) | I27: =IF(AND(ABS(G27)>Dashboard!$B$6,ISNUMBER(H27),ABS(H27)>Dashboard!$C$6),"FLAG","")
A28: ='TB_2025'!A9 | B28: ='TB_2025'!B9 | C28: ='TB_2025'!C9 | D28: Feb | E28: ='TB_2025'!E9 | F28: ='TB_2026'!E9 | G28: =F28-E28 | H28: =IF(E28=0,"",G28/ABS(E28)) | I28: =IF(AND(ABS(G28)>Dashboard!$B$6,ISNUMBER(H28),ABS(H28)>Dashboard!$C$6),"FLAG","")
A29: ='TB_2025'!A9 | B29: ='TB_2025'!B9 | C29: ='TB_2025'!C9 | D29: Mar | E29: ='TB_2025'!F9 | F29: ='TB_2026'!F9 | G29: =F29-E29 | H29: =IF(E29=0,"",G29/ABS(E29)) | I29: =IF(AND(ABS(G29)>Dashboard!$B$6,ISNUMBER(H29),ABS(H29)>Dashboard!$C$6),"FLAG","")
A30: ='TB_2025'!A9 | B30: ='TB_2025'!B9 | C30: ='TB_2025'!C9 | D30: Apr | E30: ='TB_2025'!G9 | F30: ='TB_2026'!G9 | G30: =F30-E30 | H30: =IF(E30=0,"",G30/ABS(E30)) | I30: =IF(AND(ABS(G30)>Dashboard!$B$6,ISNUMBER(H30),ABS(H30)>Dashboard!$C$6),"FLAG","")
A31: ='TB_2025'!A10 | B31: ='TB_2025'!B10 | C31: ='TB_2025'!C10 | D31: Jan | E31: ='TB_2025'!D10 | F31: ='TB_2026'!D10 | G31: =F31-E31 | H31: =IF(E31=0,"",G31/ABS(E31)) | I31: =IF(AND(ABS(G31)>Dashboard!$B$6,ISNUMBER(H31),ABS(H31)>Dashboard!$C$6),"FLAG","")
A32: ='TB_2025'!A10 | B32: ='TB_2025'!B10 | C32: ='TB_2025'!C10 | D32: Feb | E32: ='TB_2025'!E10 | F32: ='TB_2026'!E10 | G32: =F32-E32 | H32: =IF(E32=0,"",G32/ABS(E32)) | I32: =IF(AND(ABS(G32)>Dashboard!$B$6,ISNUMBER(H32),ABS(H32)>Dashboard!$C$6),"FLAG","")
A33: ='TB_2025'!A10 | B33: ='TB_2025'!B10 | C33: ='TB_2025'!C10 | D33: Mar | E33: ='TB_2025'!F10 | F33: ='TB_2026'!F10 | G33: =F33-E33 | H33: =IF(E33=0,"",G33/ABS(E33)) | I33: =IF(AND(ABS(G33)>Dashboard!$B$6,ISNUMBER(H33),ABS(H33)>Dashboard!$C$6),"FLAG","")
A34: ='TB_2025'!A10 | B34: ='TB_2025'!B10 | C34: ='TB_2025'!C10 | D34: Apr | E34: ='TB_2025'!G10 | F34: ='TB_2026'!G10 | G34: =F34-E34 | H34: =IF(E34=0,"",G34/ABS(E34)) | I34: =IF(AND(ABS(G34)>Dashboard!$B$6,ISNUMBER(H34),ABS(H34)>Dashboard!$C$6),"FLAG","")
A35: ='TB_2025'!A11 | B35: ='TB_2025'!B11 | C35: ='TB_2025'!C11 | D35: Jan | E35: ='TB_2025'!D11 | F35: ='TB_2026'!D11 | G35: =F35-E35 | H35: =IF(E35=0,"",G35/ABS(E35)) | I35: =IF(AND(ABS(G35)>Dashboard!$B$6,ISNUMBER(H35),ABS(H35)>Dashboard!$C$6),"FLAG","")
A36: ='TB_2025'!A11 | B36: ='TB_2025'!B11 | C36: ='TB_2025'!C11 | D36: Feb | E36: ='TB_2025'!E11 | F36: ='TB_2026'!E11 | G36: =F36-E36 | H36: =IF(E36=0,"",G36/ABS(E36)) | I36: =IF(AND(ABS(G36)>Dashboard!$B$6,ISNUMBER(H36),ABS(H36)>Dashboard!$C$6),"FLAG","")
A37: ='TB_2025'!A11 | B37: ='TB_2025'!B11 | C37: ='TB_2025'!C11 | D37: Mar | E37: ='TB_2025'!F11 | F37: ='TB_2026'!F11 | G37: =F37-E37 | H37: =IF(E37=0,"",G37/ABS(E37)) | I37: =IF(AND(ABS(G37)>Dashboard!$B$6,ISNUMBER(H37),ABS(H37)>Dashboard!$C$6),"FLAG","")
A38: ='TB_2025'!A11 | B38: ='TB_2025'!B11 | C38: ='TB_2025'!C11 | D38: Apr | E38: ='TB_2025'!G11 | F38: ='TB_2026'!G11 | G38: =F38-E38 | H38: =IF(E38=0,"",G38/ABS(E38)) | I38: =IF(AND(ABS(G38)>Dashboard!$B$6,ISNUMBER(H38),ABS(H38)>Dashboard!$C$6),"FLAG","")
A39: ='TB_2025'!A12 | B39: ='TB_2025'!B12 | C39: ='TB_2025'!C12 | D39: Jan | E39: ='TB_2025'!D12 | F39: ='TB_2026'!D12 | G39: =F39-E39 | H39: =IF(E39=0,"",G39/ABS(E39)) | I39: =IF(AND(ABS(G39)>Dashboard!$B$6,ISNUMBER(H39),ABS(H39)>Dashboard!$C$6),"FLAG","")
A40: ='TB_2025'!A12 | B40: ='TB_2025'!B12 | C40: ='TB_2025'!C12 | D40: Feb | E40: ='TB_2025'!E12 | F40: ='TB_2026'!E12 | G40: =F40-E40 | H40: =IF(E40=0,"",G40/ABS(E40)) | I40: =IF(AND(ABS(G40)>Dashboard!$B$6,ISNUMBER(H40),ABS(H40)>Dashboard!$C$6),"FLAG","")
...

Sheet MoM_Variance
A1: Month-over-Month Variance - sequential months, 2026 only
A2: Account Code | B2: Account | C2: Type | D2: From | E2: To | F2: Value (From) | G2: Value (To) | H2: $ Var | I2: % Var | J2: Flag
A3: ='TB_2026'!A3 | B3: ='TB_2026'!B3 | C3: ='TB_2026'!C3 | D3: Jan | E3: Feb | F3: ='TB_2026'!D3 | G3: ='TB_2026'!E3 | H3: =G3-F3 | I3: =IF(F3=0,"",H3/ABS(F3)) | J3: =IF(AND(ABS(H3)>Dashboard!$B$7,ISNUMBER(I3),ABS(I3)>Dashboard!$C$7),"FLAG","")
A4: ='TB_2026'!A3 | B4: ='TB_2026'!B3 | C4: ='TB_2026'!C3 | D4: Feb | E4: Mar | F4: ='TB_2026'!E3 | G4: ='TB_2026'!F3 | H4: =G4-F4 | I4: =IF(F4=0,"",H4/ABS(F4)) | J4: =IF(AND(ABS(H4)>Dashboard!$B$7,ISNUMBER(I4),ABS(I4)>Dashboard!$C$7),"FLAG","")
A5: ='TB_2026'!A3 | B5: ='TB_2026'!B3 | C5: ='TB_2026'!C3 | D5: Mar | E5: Apr | F5: ='TB_2026'!F3 | G5: ='TB_2026'!G3 | H5: =G5-F5 | I5: =IF(F5=0,"",H5/ABS(F5)) | J5: =IF(AND(ABS(H5)>Dashboard!$B$7,ISNUMBER(I5),ABS(I5)>Dashboard!$C$7),"FLAG","")
A6: ='TB_2026'!A4 | B6: ='TB_2026'!B4 | C6: ='TB_2026'!C4 | D6: Jan | E6: Feb | F6: ='TB_2026'!D4 | G6: ='TB_2026'!E4 | H6: =G6-F6 | I6: =IF(F6=0,"",H6/ABS(F6)) | J6: =IF(AND(ABS(H6)>Dashboard!$B$7,ISNUMBER(I6),ABS(I6)>Dashboard!$C$7),"FLAG","")
A7: ='TB_2026'!A4 | B7: ='TB_2026'!B4 | C7: ='TB_2026'!C4 | D7: Feb | E7: Mar | F7: ='TB_2026'!E4 | G7: ='TB_2026'!F4 | H7: =G7-F7 | I7: =IF(F7=0,"",H7/ABS(F7)) | J7: =IF(AND(ABS(H7)>Dashboard!$B$7,ISNUMBER(I7),ABS(I7)>Dashboard!$C$7),"FLAG","")
A8: ='TB_2026'!A4 | B8: ='TB_2026'!B4 | C8: ='TB_2026'!C4 | D8: Mar | E8: Apr | F8: ='TB_2026'!F4 | G8: ='TB_2026'!G4 | H8: =G8-F8 | I8: =IF(F8=0,"",H8/ABS(F8)) | J8: =IF(AND(ABS(H8)>Dashboard!$B$7,ISNUMBER(I8),ABS(I8)>Dashboard!$C$7),"FLAG","")
A9: ='TB_2026'!A5 | B9: ='TB_2026'!B5 | C9: ='TB_2026'!C5 | D9: Jan | E9: Feb | F9: ='TB_2026'!D5 | G9: ='TB_2026'!E5 | H9: =G9-F9 | I9: =IF(F9=0,"",H9/ABS(F9)) | J9: =IF(AND(ABS(H9)>Dashboard!$B$7,ISNUMBER(I9),ABS(I9)>Dashboard!$C$7),"FLAG","")
A10: ='TB_2026'!A5 | B10: ='TB_2026'!B5 | C10: ='TB_2026'!C5 | D10: Feb | E10: Mar | F10: ='TB_2026'!E5 | G10: ='TB_2026'!F5 | H10: =G10-F10 | I10: =IF(F10=0,"",H10/ABS(F10)) | J10: =IF(AND(ABS(H10)>Dashboard!$B$7,ISNUMBER(I10),ABS(I10)>Dashboard!$C$7),"FLAG","")
A11: ='TB_2026'!A5 | B11: ='TB_2026'!B5 | C11: ='TB_2026'!C5 | D11: Mar | E11: Apr | F11: ='TB_2026'!F5 | G11: ='TB_2026'!G5 | H11: =G11-F11 | I11: =IF(F11=0,"",H11/ABS(F11)) | J11: =IF(AND(ABS(H11)>Dashboard!$B$7,ISNUMBER(I11),ABS(I11)>Dashboard!$C$7),"FLAG","")
A12: ='TB_2026'!A6 | B12: ='TB_2026'!B6 | C12: ='TB_2026'!C6 | D12: Jan | E12: Feb | F12: ='TB_2026'!D6 | G12: ='TB_2026'!E6 | H12: =G12-F12 | I12: =IF(F12=0,"",H12/ABS(F12)) | J12: =IF(AND(ABS(H12)>Dashboard!$B$7,ISNUMBER(I12),ABS(I12)>Dashboard!$C$7),"FLAG","")
A13: ='TB_2026'!A6 | B13: ='TB_2026'!B6 | C13: ='TB_2026'!C6 | D13: Feb | E13: Mar | F13: ='TB_2026'!E6 | G13: ='TB_2026'!F6 | H13: =G13-F13 | I13: =IF(F13=0,"",H13/ABS(F13)) | J13: =IF(AND(ABS(H13)>Dashboard!$B$7,ISNUMBER(I13),ABS(I13)>Dashboard!$C$7),"FLAG","")
A14: ='TB_2026'!A6 | B14: ='TB_2026'!B6 | C14: ='TB_2026'!C6 | D14: Mar | E14: Apr | F14: ='TB_2026'!F6 | G14: ='TB_2026'!G6 | H14: =G14-F14 | I14: =IF(F14=0,"",H14/ABS(F14)) | J14: =IF(AND(ABS(H14)>Dashboard!$B$7,ISNUMBER(I14),ABS(I14)>Dashboard!$C$7),"FLAG","")
A15: ='TB_2026'!A7 | B15: ='TB_2026'!B7 | C15: ='TB_2026'!C7 | D15: Jan | E15: Feb | F15: ='TB_2026'!D7 | G15: ='TB_2026'!E7 | H15: =G15-F15 | I15: =IF(F15=0,"",H15/ABS(F15)) | J15: =IF(AND(ABS(H15)>Dashboard!$B$7,ISNUMBER(I15),ABS(I15)>Dashboard!$C$7),"FLAG","")
A16: ='TB_2026'!A7 | B16: ='TB_2026'!B7 | C16: ='TB_2026'!C7 | D16: Feb | E16: Mar | F16: ='TB_2026'!E7 | G16: ='TB_2026'!F7 | H16: =G16-F16 | I16: =IF(F16=0,"",H16/ABS(F16)) | J16: =IF(AND(ABS(H16)>Dashboard!$B$7,ISNUMBER(I16),ABS(I16)>Dashboard!$C$7),"FLAG","")
A17: ='TB_2026'!A7 | B17: ='TB_2026'!B7 | C17: ='TB_2026'!C7 | D17: Mar | E17: Apr | F17: ='TB_2026'!F7 | G17: ='TB_2026'!G7 | H17: =G17-F17 | I17: =IF(F17=0,"",H17/ABS(F17)) | J17: =IF(AND(ABS(H17)>Dashboard!$B$7,ISNUMBER(I17),ABS(I17)>Dashboard!$C$7),"FLAG","")
A18: ='TB_2026'!A8 | B18: ='TB_2026'!B8 | C18: ='TB_2026'!C8 | D18: Jan | E18: Feb | F18: ='TB_2026'!D8 | G18: ='TB_2026'!E8 | H18: =G18-F18 | I18: =IF(F18=0,"",H18/ABS(F18)) | J18: =IF(AND(ABS(H18)>Dashboard!$B$7,ISNUMBER(I18),ABS(I18)>Dashboard!$C$7),"FLAG","")
A19: ='TB_2026'!A8 | B19: ='TB_2026'!B8 | C19: ='TB_2026'!C8 | D19: Feb | E19: Mar | F19: ='TB_2026'!E8 | G19: ='TB_2026'!F8 | H19: =G19-F19 | I19: =IF(F19=0,"",H19/ABS(F19)) | J19: =IF(AND(ABS(H19)>Dashboard!$B$7,ISNUMBER(I19),ABS(I19)>Dashboard!$C$7),"FLAG","")
A20: ='TB_2026'!A8 | B20: ='TB_2026'!B8 | C20: ='TB_2026'!C8 | D20: Mar | E20: Apr | F20: ='TB_2026'!F8 | G20: ='TB_2026'!G8 | H20: =G20-F20 | I20: =IF(F20=0,"",H20/ABS(F20)) | J20: =IF(AND(ABS(H20)>Dashboard!$B$7,ISNUMBER(I20),ABS(I20)>Dashboard!$C$7),"FLAG","")
A21: ='TB_2026'!A9 | B21: ='TB_2026'!B9 | C21: ='TB_2026'!C9 | D21: Jan | E21: Feb | F21: ='TB_2026'!D9 | G21: ='TB_2026'!E9 | H21: =G21-F21 | I21: =IF(F21=0,"",H21/ABS(F21)) | J21: =IF(AND(ABS(H21)>Dashboard!$B$7,ISNUMBER(I21),ABS(I21)>Dashboard!$C$7),"FLAG","")
A22: ='TB_2026'!A9 | B22: ='TB_2026'!B9 | C22: ='TB_2026'!C9 | D22: Feb | E22: Mar | F22: ='TB_2026'!E9 | G22: ='TB_2026'!F9 | H22: =G22-F22 | I22: =IF(F22=0,"",H22/ABS(F22)) | J22: =IF(AND(ABS(H22)>Dashboard!$B$7,ISNUMBER(I22),ABS(I22)>Dashboard!$C$7),"FLAG","")
A23: ='TB_2026'!A9 | B23: ='TB_2026'!B9 | C23: ='TB_2026'!C9 | D23: Mar | E23: Apr | F23: ='TB_2026'!F9 | G23: ='TB_2026'!G9 | H23: =G23-F23 | I23: =IF(F23=0,"",H23/ABS(F23)) | J23: =IF(AND(ABS(H23)>Dashboard!$B$7,ISNUMBER(I23),ABS(I23)>Dashboard!$C$7),"FLAG","")
A24: ='TB_2026'!A10 | B24: ='TB_2026'!B10 | C24: ='TB_2026'!C10 | D24: Jan | E24: Feb | F24: ='TB_2026'!D10 | G24: ='TB_2026'!E10 | H24: =G24-F24 | I24: =IF(F24=0,"",H24/ABS(F24)) | J24: =IF(AND(ABS(H24)>Dashboard!$B$7,ISNUMBER(I24),ABS(I24)>Dashboard!$C$7),"FLAG","")
A25: ='TB_2026'!A10 | B25: ='TB_2026'!B10 | C25: ='TB_2026'!C10 | D25: Feb | E25: Mar | F25: ='TB_2026'!E10 | G25: ='TB_2026'!F10 | H25: =G25-F25 | I25: =IF(F25=0,"",H25/ABS(F25)) | J25: =IF(AND(ABS(H25)>Dashboard!$B$7,ISNUMBER(I25),ABS(I25)>Dashboard!$C$7),"FLAG","")
A26: ='TB_2026'!A10 | B26: ='TB_2026'!B10 | C26: ='TB_2026'!C10 | D26: Mar | E26: Apr | F26: ='TB_2026'!F10 | G26: ='TB_2026'!G10 | H26: =G26-F26 | I26: =IF(F26=0,"",H26/ABS(F26)) | J26: =IF(AND(ABS(H26)>Dashboard!$B$7,ISNUMBER(I26),ABS(I26)>Dashboard!$C$7),"FLAG","")
A27: ='TB_2026'!A11 | B27: ='TB_2026'!B11 | C27: ='TB_2026'!C11 | D27: Jan | E27: Feb | F27: ='TB_2026'!D11 | G27: ='TB_2026'!E11 | H27: =G27-F27 | I27: =IF(F27=0,"",H27/ABS(F27)) | J27: =IF(AND(ABS(H27)>Dashboard!$B$7,ISNUMBER(I27),ABS(I27)>Dashboard!$C$7),"FLAG","")
A28: ='TB_2026'!A11 | B28: ='TB_2026'!B11 | C28: ='TB_2026'!C11 | D28: Feb | E28: Mar | F28: ='TB_2026'!E11 | G28: ='TB_2026'!F11 | H28: =G28-F28 | I28: =IF(F28=0,"",H28/ABS(F28)) | J28: =IF(AND(ABS(H28)>Dashboard!$B$7,ISNUMBER(I28),ABS(I28)>Dashboard!$C$7),"FLAG","")
A29: ='TB_2026'!A11 | B29: ='TB_2026'!B11 | C29: ='TB_2026'!C11 | D29: Mar | E29: Apr | F29: ='TB_2026'!F11 | G29: ='TB_2026'!G11 | H29: =G29-F29 | I29: =IF(F29=0,"",H29/ABS(F29)) | J29: =IF(AND(ABS(H29)>Dashboard!$B$7,ISNUMBER(I29),ABS(I29)>Dashboard!$C$7),"FLAG","")
A30: ='TB_2026'!A12 | B30: ='TB_2026'!B12 | C30: ='TB_2026'!C12 | D30: Jan | E30: Feb | F30: ='TB_2026'!D12 | G30: ='TB_2026'!E12 | H30: =G30-F30 | I30: =IF(F30=0,"",H30/ABS(F30)) | J30: =IF(AND(ABS(H30)>Dashboard!$B$7,ISNUMBER(I30),ABS(I30)>Dashboard!$C$7),"FLAG","")
A31: ='TB_2026'!A12 | B31: ='TB_2026'!B12 | C31: ='TB_2026'!C12 | D31: Feb | E31: Mar | F31: ='TB_2026'!E12 | G31: ='TB_2026'!F12 | H31: =G31-F31 | I31: =IF(F31=0,"",H31/ABS(F31)) | J31: =IF(AND(ABS(H31)>Dashboard!$B$7,ISNUMBER(I31),ABS(I31)>Dashboard!$C$7),"FLAG","")
A32: ='TB_2026'!A12 | B32: ='TB_2026'!B12 | C32: ='TB_2026'!C12 | D32: Mar | E32: Apr | F32: ='TB_2026'!F12 | G32: ='TB_2026'!G12 | H32: =G32-F32 | I32: =IF(F32=0,"",H32/ABS(F32)) | J32: =IF(AND(ABS(H32)>Dashboard!$B$7,ISNUMBER(I32),ABS(I32)>Dashboard!$C$7),"FLAG","")
A33: ='TB_2026'!A13 | B33: ='TB_2026'!B13 | C33: ='TB_2026'!C13 | D33: Jan | E33: Feb | F33: ='TB_2026'!D13 | G33: ='TB_2026'!E13 | H33: =G33-F33 | I33: =IF(F33=0,"",H33/ABS(F33)) | J33: =IF(AND(ABS(H33)>Dashboard!$B$7,ISNUMBER(I33),ABS(I33)>Dashboard!$C$7),"FLAG","")
A34: ='TB_2026'!A13 | B34: ='TB_2026'!B13 | C34: ='TB_2026'!C13 | D34: Feb | E34: Mar | F34: ='TB_2026'!E13 | G34: ='TB_2026'!F13 | H34: =G34-F34 | I34: =IF(F34=0,"",H34/ABS(F34)) | J34: =IF(AND(ABS(H34)>Dashboard!$B$7,ISNUMBER(I34),ABS(I34)>Dashboard!$C$7),"FLAG","")
A35: ='TB_2026'!A13 | B35: ='TB_2026'!B13 | C35: ='TB_2026'!C13 | D35: Mar | E35: Apr | F35: ='TB_2026'!F13 | G35: ='TB_2026'!G13 | H35: =G35-F35 | I35: =IF(F35=0,"",H35/ABS(F35)) | J35: =IF(AND(ABS(H35)>Dashboard!$B$7,ISNUMBER(I35),ABS(I35)>Dashboard!$C$7),"FLAG","")
A36: ='TB_2026'!A14 | B36: ='TB_2026'!B14 | C36: ='TB_2026'!C14 | D36: Jan | E36: Feb | F36: ='TB_2026'!D14 | G36: ='TB_2026'!E14 | H36: =G36-F36 | I36: =IF(F36=0,"",H36/ABS(F36)) | J36: =IF(AND(ABS(H36)>Dashboard!$B$7,ISNUMBER(I36),ABS(I36)>Dashboard!$C$7),"FLAG","")
A37: ='TB_2026'!A14 | B37: ='TB_2026'!B14 | C37: ='TB_2026'!C14 | D37: Feb | E37: Mar | F37: ='TB_2026'!E14 | G37: ='TB_2026'!F14 | H37: =G37-F37 | I37: =IF(F37=0,"",H37/ABS(F37)) | J37: =IF(AND(ABS(H37)>Dashboard!$B$7,ISNUMBER(I37),ABS(I37)>Dashboard!$C$7),"FLAG","")
A38: ='TB_2026'!A14 | B38: ='TB_2026'!B14 | C38: ='TB_2026'!C14 | D38: Mar | E38: Apr | F38: ='TB_2026'!F14 | G38: ='TB_2026'!G14 | H38: =G38-F38 | I38: =IF(F38=0,"",H38/ABS(F38)) | J38: =IF(AND(ABS(H38)>Dashboard!$B$7,ISNUMBER(I38),ABS(I38)>Dashboard!$C$7),"FLAG","")
A39: ='TB_2026'!A15 | B39: ='TB_2026'!B15 | C39: ='TB_2026'!C15 | D39: Jan | E39: Feb | F39: ='TB_2026'!D15 | G39: ='TB_2026'!E15 | H39: =G39-F39 | I39: =IF(F39=0,"",H39/ABS(F39)) | J39: =IF(AND(ABS(H39)>Dashboard!$B$7,ISNUMBER(I39),ABS(I39)>Dashboard!$C$7),"FLAG","")
A40: ='TB_2026'!A15 | B40: ='TB_2026'!B15 | C40: ='TB_2026'!C15 | D40: Feb | E40: Mar | F40: ='TB_2026'!E15 | G40: ='TB_2026'!F15 | H40: =G40-F40 | I40: =IF(F40=0,"",H40/ABS(F40)) | J40: =IF(AND(ABS(H40)>Dashboard!$B$7,ISNUMBER(I40),ABS(I40)>Dashboard!$C$7),"FLAG","")
...

Sheet Flagged_Summary
A1: Flagged Accounts - every cell below traces to YoY_Variance / MoM_Variance
A2: Type | B2: Account | C2: Period | D2: $ Var | E2: % Var | F2: Note
A3: YoY | B3: =YoY_Variance!B3 | C3: =YoY_Variance!D3 | D3: =YoY_Variance!G3 | E3: =YoY_Variance!H3
A4: YoY | B4: =YoY_Variance!B4 | C4: =YoY_Variance!D4 | D4: =YoY_Variance!G4 | E4: =YoY_Variance!H4
A5: YoY | B5: =YoY_Variance!B5 | C5: =YoY_Variance!D5 | D5: =YoY_Variance!G5 | E5: =YoY_Variance!H5
A6: YoY | B6: =YoY_Variance!B6 | C6: =YoY_Variance!D6 | D6: =YoY_Variance!G6 | E6: =YoY_Variance!H6
A7: YoY | B7: =YoY_Variance!B14 | C7: =YoY_Variance!D14 | D7: =YoY_Variance!G14 | E7: =YoY_Variance!H14 | F7: Balloons in April 2026 specifically - invisible in a single month, obvious once diffed.
A8: YoY | B8: =YoY_Variance!B31 | C8: =YoY_Variance!D31 | D8: =YoY_Variance!G31 | E8: =YoY_Variance!H31
A9: YoY | B9: =YoY_Variance!B32 | C9: =YoY_Variance!D32 | D9: =YoY_Variance!G32 | E9: =YoY_Variance!H32
A10: YoY | B10: =YoY_Variance!B33 | C10: =YoY_Variance!D33 | D10: =YoY_Variance!G33 | E10: =YoY_Variance!H33
A11: YoY | B11: =YoY_Variance!B34 | C11: =YoY_Variance!D34 | D11: =YoY_Variance!G34 | E11: =YoY_Variance!H34
A12: YoY | B12: =YoY_Variance!B59 | C12: =YoY_Variance!D59 | D12: =YoY_Variance!G59 | E12: =YoY_Variance!H59
A13: YoY | B13: =YoY_Variance!B60 | C13: =YoY_Variance!D60 | D13: =YoY_Variance!G60 | E13: =YoY_Variance!H60
A14: YoY | B14: =YoY_Variance!B61 | C14: =YoY_Variance!D61 | D14: =YoY_Variance!G61 | E14: =YoY_Variance!H61
A15: YoY | B15: =YoY_Variance!B62 | C15: =YoY_Variance!D62 | D15: =YoY_Variance!G62 | E15: =YoY_Variance!H62
A16: YoY | B16: =YoY_Variance!B70 | C16: =YoY_Variance!D70 | D16: =YoY_Variance!G70 | E16: =YoY_Variance!H70
A17: YoY | B17: =YoY_Variance!B85 | C17: =YoY_Variance!D85 | D17: =YoY_Variance!G85 | E17: =YoY_Variance!H85 | F17: Consistent with vendor cost inflation noted in Article 01 - dated and quantified here.
A18: YoY | B18: =YoY_Variance!B86 | C18: =YoY_Variance!D86 | D18: =YoY_Variance!G86 | E18: =YoY_Variance!H86 | F18: Consistent with vendor cost inflation noted in Article 01 - dated and quantified here.
A19: YoY | B19: =YoY_Variance!B105 | C19: =YoY_Variance!D105 | D19: =YoY_Variance!G105 | E19: =YoY_Variance!H105 | F19: One-month spike, not present in the prior year at all - real campaign or miscoded invoice?
A20: MoM | B20: =MoM_Variance!B11 | C20: =MoM_Variance!D11&"->"&MoM_Variance!E11 | D20: =MoM_Variance!H11 | E20: =MoM_Variance!I11 | F20: Balloons in April 2026 specifically - invisible in a single month, obvious once diffed.
A21: MoM | B21: =MoM_Variance!B53 | C21: =MoM_Variance!D53&"->"&MoM_Variance!E53 | D21: =MoM_Variance!H53 | E21: =MoM_Variance!I53
A22: MoM | B22: =MoM_Variance!B64 | C22: =MoM_Variance!D64&"->"&MoM_Variance!E64 | D22: =MoM_Variance!H64 | E22: =MoM_Variance!I64
A23: MoM | B23: =MoM_Variance!B79 | C23: =MoM_Variance!D79&"->"&MoM_Variance!E79 | D23: =MoM_Variance!H79 | E23: =MoM_Variance!I79 | F23: One-month spike, not present in the prior year at all - real campaign or miscoded invoice?
A24: MoM | B24: =MoM_Variance!B80 | C24: =MoM_Variance!D80&"->"&MoM_Variance!E80 | D24: =MoM_Variance!H80 | E24: =MoM_Variance!I80 | F24: One-month spike, not present in the prior year at all - real campaign or miscoded invoice?
A25: MoM | B25: =MoM_Variance!B87 | C25: =MoM_Variance!D87&"->"&MoM_Variance!E87 | D25: =MoM_Variance!H87 | E25: =MoM_Variance!I87 | F25: Recurring seasonal pattern - same February spike both years. Not a surprise; flagged here because MoM measures sequential movement, not because it's new.
A26: MoM | B26: =MoM_Variance!B88 | C26: =MoM_Variance!D88&"->"&MoM_Variance!E88 | D26: =MoM_Variance!H88 | E26: =MoM_Variance!I88 | F26: Recurring seasonal pattern - same February spike both years. Not a surprise; flagged here because MoM measures sequential movement, not because it's new.
